Workbook
Name BD: #REF!

Sheet Email Ids for Billing Mails
A1: # | B1: Project Name | C1: CC | D1: Payee name | E1: Billing Company Name | F1: Hardcopy needed (Yes/No) | G1: To | H1: cc List (external) | I1: cc to CMES Team (O&M, Minal, Kumar) | J1: Contact Numbers | K1: Contact Number - Collections Specific | L1: Invoiced by
A2: 1 | B2: Agharkar-MH-Pune-100.79kWp Total | C2: =VLOOKUP(B2,Sheet1!B2:D486,2,0) -> West | D2: Maharastra Association for cultivation of Science | E2: CMES | F2: Yes | G2: A V Chaudhari <avchaudhari@aripune.org>, Rahul G Birwadkar <rbirwadkar@aripune.org>, pv sawant <pvsawant@aripune.org>, Minal Vithlani <minal.vithlani@cleanmax.com>, "accounts ." <accounts@aripune.org>, Logesh B <logesh.b@cleanmax.com>, Prasad Kulkarni <prasad.kulkarni@cleanmax.com>, Kumaravel R <kumaravel.r@cleanmax.com> | H2: accounts@aripune.org | L2: =VLOOKUP(C2,Sheet1!A1:E477,2,0) -> #N/A
A3: 2 | B3: Manipal Resorts-KA-Bangalore-135kWp Total | C3: =VLOOKUP(B3,Sheet1!B3:D487,2,0) -> South | D3: Manipal Resorts Co Pvt Ltd | E3: CMES | F3: No | G3: kshitij.mohan@manipalglobal.com; naresh.shanmugam@manipalglobal.com; sunil.v@manipalglobal.com | L3: =VLOOKUP(C3,Sheet1!A2:E478,2,0) -> #N/A
A4: 3 | B4: Medha Servo-TS-Hyderabad-252kWp Total | C4: =VLOOKUP(B4,Sheet1!B4:D488,2,0) -> South | D4: Medha Servo Drives Pvt Ltd | E4: CMES | F4: No | G4: sudhakark@medha.com; sasikalat@medha.com; nagenderkumark@medha.com; | L4: =VLOOKUP(C4,Sheet1!A3:E479,2,0) -> #N/A
A5: 4 | B5: Nestle-HR-Samalkha-300kWp Total | C5: =VLOOKUP(B5,Sheet1!B5:D489,2,0) -> North | D5: Nestle India Ltd | E5: CMES | F5: No | G5: Generic.INInvoiceSAR01@in.nestle.com | H5: vikas.patil@cleanmax.com | L5: =VLOOKUP(C5,Sheet1!A4:E480,2,0) -> #N/A
A6: 5 | B6: Mahindra & Mahindra-MH-Nagpur-235kWp Total | C6: =VLOOKUP(B6,Sheet1!B6:D490,2,0) -> West | D6: Mahindra & Mahindra Limited | E6: CMES | F6: No | G6: JAIN RITESH-NGP <JAIN.RITESH1@mahindra.com>,JUNGHARE GUNWANTA <JUNGHARE.GUNWANTA@mahindra.com>, GOTMARE SURAJ <GOTMARE.SURAJ@mahindra.com>, Minal Vithlani <minal.vithlani@cleanmax.com>, Satish Chavan <satish.chavan@cleanmax.com>, Logesh B <logesh.b@cleanmax.com>, Kumaravel R <kumaravel.r@cleanmax.com>, Akshay Mohale <akshay.mohale@cleanmax.com> | H6: BHARADWAJ.SHUBHOMOY@mahindra.com;213420@mahindra.com | L6: =VLOOKUP(C6,Sheet1!A5:E481,2,0) -> #N/A
A7: 6 | B7: CPWD-MH-Pune-151kWp Total | C7: =VLOOKUP(B7,Sheet1!B7:D491,2,0) -> West | D7: Central Excise & Service Tax-Pune-II | E7: CMES | F7: Yes | G7: lbpune2@gmail.com | L7: =VLOOKUP(C7,Sheet1!A6:E482,2,0) -> #N/A
A8: 7 | B8: MMM Sanand-GJ-Ahmedabad-192kWp Total | C8: =VLOOKUP(B8,Sheet1!B8:D492,2,0) -> West | D8: Magneti Marelli Motherson Auto Systems Pvt Ltd | E8: CMES | F8: No | G8: "Rawat Vinod (MMLI)" <Vinod.rawat@marelli.motherson.com>, "Jagtap, Prasad (MMLI)" <Prasad.Jagtap@marelli.motherson.com>, Kumaravel R <kumaravel.r@cleanmax.com>, Yash Lavhate <yash.lavhate@cleanmax.com>; hiteshk.rohilla@marelli.motherson.com; Naveen.Agarwal01@marelli.motherson.com; maint.sanand@marelli.motherson.com | H8: anupam@marelli.motherson.com;shailesh.sakhare@marelli.motherson.com;Vinod.rawat@marelli.motherson.com | L8: =VLOOKUP(C8,Sheet1!A7:E483,2,0) -> #N/A
A9: 8 | B9: CPWD-UP-Agra-50kWp Total | C9: =VLOOKUP(B9,Sheet1!B9:D493,2,0) -> North | D9: Agra Central Electrical Division | E9: CMES | F9: Yes | G9: acesd.agra@gmail.com;eebced@rediffmail.com | L9: =VLOOKUP(C9,Sheet1!A8:E484,2,0) -> #N/A
A10: 9 | B10: CPWD-KA-Bangalore-75.6kWp Total | C10: =VLOOKUP(B10,Sheet1!B10:D494,2,0) -> South | D10: Bangalore Central Electrical Division | E10: CMES | F10: Yes | G10: vidhyaslm@gmail.com;raj.danny27@gmail.com | L10: =VLOOKUP(C10,Sheet1!A9:E485,2,0) -> #N/A
A11: 10 | B11: IIT-BHU-UP-Varanasi-1518kWp Total | C11: =VLOOKUP(B11,Sheet1!B11:D495,2,0) -> North | D11: Indian Institute of Technology Banaras Hindu University | E11: CMES | F11: Yes | G11: Office.iwd@iitbhu.ac.in;sbd.civ@iitbhu.ac.in;aecivil.iwd@itbhu.ac.in | H11: skgupta.civ@iitbhu.ac.in | L11: =VLOOKUP(C11,Sheet1!A10:E486,2,0) -> #N/A
A12: 11 | B12: Kendriya Sadan-TS-Hyderabad-100.8kWp Total | C12: =VLOOKUP(B12,Sheet1!B12:D495,2,0) -> South | D12: Executive Engineer, HCED II, CPWD Telengana | E12: CMES | F12: Yes | G12: hcesd5cpwd@gmail.com | H12: sivacpwd@gmail.com | L12: =VLOOKUP(C12,Sheet1!A11:E487,2,0) -> #N/A
A13: 12 | B13: Kendriya Sadan-MH-Belapur-37kWp Total | C13: =VLOOKUP(B13,Sheet1!B13:D495,2,0) -> West | D13: Executive Engineer, CPWD, Belapur | E13: CMES | F13: Yes | G13: MCED V <eeemcedv@gmail.com>, shachendra@yahoo.co.in, Kumaravel R <kumaravel.r@cleanmaxsolar.com>, Logesh B <logesh.b@cleanmax.com>, Minal Vithlani <minal.vithlani@cleanmax.com>, AEE3 MCED <aee3mced3cpwd@gmail.com>, Rakesh Kumar Sharma <sharmacpwd@gmail.com>, Assistant Engineer Mced <aee3mcedv@gmail.com>, "Westteam.am" <westteam.am@cleanmax.com> | H13: aee3mced3cpwd@gmail.com;sharmacpwd@gmail.com;aee3mcedv@gmail.com | L13: =VLOOKUP(C13,Sheet1!A12:E488,2,0) -> #N/A
A14: 13 | B14: CGO-MH-Belapur-50.4kWp Total | C14: =VLOOKUP(B14,Sheet1!B14:D496,2,0) -> West | D14: Executive Engineer, CPWD, Mumbai | E14: CMES | F14: Yes | G14: MCED V <eeemcedv@gmail.com>, shachendra@yahoo.co.in, Kumaravel R <kumaravel.r@cleanmaxsolar.com>, Logesh B <logesh.b@cleanmax.com>, Minal Vithlani <minal.vithlani@cleanmax.com>, AEE3 MCED <aee3mced3cpwd@gmail.com>, Rakesh Kumar Sharma <sharmacpwd@gmail.com>, Assistant Engineer Mced <aee3mcedv@gmail.com>, "Westteam.am" <westteam.am@cleanmax.com> | H14: aee3mced3cpwd@gmail.com;sharmacpwd@gmail.com;aee3mcedv@gmail.com | L14: =VLOOKUP(C14,Sheet1!A13:E489,2,0) -> #N/A
A15: 14 | B15: CPWD-MH-Mumbai-50kWp Total | C15: =VLOOKUP(B15,Sheet1!B15:D497,2,0) -> West | D15: Executive Engineer, CPWD Marinelines Mumbai | E15: CMES | F15: Yes | G15: sd2 mced1 <sd2_mced1@yahoo.co.in> | L15: =VLOOKUP(C15,Sheet1!A14:E490,2,0) -> #N/A
A16: 15 | B16: CGO Complex-UP-Ghaziabad-126kWp Total | C16: =VLOOKUP(B16,Sheet1!B16:D498,2,0) -> North | D16: CGO Complex, Ghaziabad | E16: CMES | F16: Yes | G16: aee1gcesd1hcedcpwd@gmail.com | H16: kamal.kk.05@gmail.com | L16: =VLOOKUP(C16,Sheet1!A15:E491,2,0) -> #N/A
A17: 16 | B17: GPO-UP-Ghaziabad-113kWp Total | C17: =VLOOKUP(B17,Sheet1!B17:D499,2,0) -> North | D17: GPO, Ghaziabad | E17: CMES | F17: Yes | G17: aee1gcesd1hcedcpwd@gmail.com | H17: kamal.kk.05@gmail.com | L17: =VLOOKUP(C17,Sheet1!A16:E492,2,0) -> #N/A
A18: 17 | B18: RAF-UP-Meerut-75kWp Total | C18: =VLOOKUP(B18,Sheet1!B18:D500,2,0) -> North | D18: Rapid Action Force (RAF) | E18: CMES | F18: Yes | G18: computercell108raf@gmail.com;sandeep108bn@gmail.com | L18: =VLOOKUP(C18,Sheet1!A17:E493,2,0) -> #N/A
A19: 18 | B19: NVTI-UP-Noida-115kWp Total | C19: =VLOOKUP(B19,Sheet1!B19:D501,2,0) -> North | D19: National Vocational Training Institute (NVTI) | E19: CMES | F19: Yes | G19: nvti@nic.in | L19: =VLOOKUP(C19,Sheet1!A18:E494,2,0) -> #N/A
A20: 19 | B20: MHEL-CHAKAN-MH-Pune-64kWp Total | C20: =VLOOKUP(B20,Sheet1!B20:D502,2,0) -> West | D20: Mahindra Heavy Engines Limited | E20: CMES | F20: No | G20: ENCHALWAR GAJANAN - MHEL <ENCHALWAR.GAJANAN@mahindra.com>, Prasad Kulkarni <prasad.kulkarni@cleanmax.com>, CHAVAN HEMANT-MHEL <CHAVAN.HEMANT@mahindra.com>, Minal Vithlani <minal.vithlani@cleanmax.com>, KUMAR ADITYA - MHEL <KUMAR.ADITYA203d22@mahindra.com>, Kumaravel R <kumaravel.r@cleanmax.com>, Logesh B <logesh.b@cleanmax.com> | H20: Kakade.Pankaj@mahindra.com;CHAVAN.HEMANT@mahindra.com; | L20: =VLOOKUP(C20,Sheet1!A19:E495,2,0) -> #N/A
A21: 20 | B21: MHEL-CHAKAN-MH-Pune-211kWp Total | C21: =VLOOKUP(B21,Sheet1!B21:D503,2,0) -> West | D21: Mahindra Heavy Engines Limited | E21: CMES | F21: No | G21: ENCHALWAR GAJANAN - MHEL <ENCHALWAR.GAJANAN@mahindra.com>, Prasad Kulkarni <prasad.kulkarni@cleanmax.com>, CHAVAN HEMANT-MHEL <CHAVAN.HEMANT@mahindra.com>, Minal Vithlani <minal.vithlani@cleanmax.com>, KUMAR ADITYA - MHEL <KUMAR.ADITYA203d22@mahindra.com>, Kumaravel R <kumaravel.r@cleanmax.com>, Logesh B <logesh.b@cleanmax.com> | H21: Kakade.Pankaj@mahindra.com;CHAVAN.HEMANT@mahindra.com | L21: =VLOOKUP(C21,Sheet1!A20:E495,2,0) -> #N/A
A22: 21 | B22: KIOCL-KA-Mangalore-191.2kWp Total | C22: =VLOOKUP(B22,Sheet1!B22:D504,2,0) -> South | D22: Kudremukh Iron Ore Company Limited | E22: CMES | F22: No | L22: =VLOOKUP(C22,Sheet1!A21:E495,2,0) -> #N/A
A23: 22 | B23: KIOCL-KA-Mangalore-102.4kWp Total | C23: =VLOOKUP(B23,Sheet1!B23:D504,2,0) -> South | D23: Kudremukh Iron Ore Company Limited | E23: CMES | F23: No | L23: =VLOOKUP(C23,Sheet1!A22:E496,2,0) -> #N/A
A24: 23 | B24: KIOCL-KA-Mangalore-83.2kWp Total | C24: =VLOOKUP(B24,Sheet1!B24:D505,2,0) -> South | D24: Kudremukh Iron Ore Company Limited | E24: CMES | F24: No | G24: mcpp@kioclltd.com; | L24: =VLOOKUP(C24,Sheet1!A23:E497,2,0) -> #N/A
A25: 24 | B25: Mahindra & Mahindra-RJ-Jaipur-269kWp Total | C25: =VLOOKUP(B25,Sheet1!B25:D506,2,0) -> West | D25: Mahindra & Mahindra Ltd | E25: CMES | F25: No | G25: kumar.manoj100@mahindra.com; YADAV.RAJESHKUMAR@mahindra.com;kuldeep.choudhary2@mahindra.com;23074175@mahindra.com | H25: shrivastava.mukesh2@mahindra.com;JAIN.ASHISH5@mahindra.com;yadav.satyaprakash@mahindra.comsingh.surendra8@mahindra.com;Dubey.sunil2@mahindra.com;singh.asim@mahindra.com;mantri.anant@mahindra.com | L25: =VLOOKUP(C25,Sheet1!A24:E498,2,0) -> #N/A
A26: 25 | B26: AMU-UP-Aligarh-1141.1kWp Total | C26: =VLOOKUP(B26,Sheet1!B26:D507,2,0) -> North | D26: Aligarh Muslim University | E26: CMES | F26: Yes | G26: m.rihan.ee@amu.ac.in;shamim_3747@rediffmail.com | L26: =VLOOKUP(C26,Sheet1!A25:E499,2,0) -> #N/A
A27: 26 | B27: AMU-UP-Aligarh-359.8kWp Total | C27: =VLOOKUP(B27,Sheet1!B27:D508,2,0) -> North | D27: Aligarh Muslim University | E27: CMES | F27: Yes | G27: m.rihan.ee@amu.ac.in;shamim_3747@rediffmail.com | L27: =VLOOKUP(C27,Sheet1!A26:E500,2,0) -> #N/A
A28: 27 | B28: Unitech Sec-21-HR-Gurugram-333.9kWp Total | C28: =VLOOKUP(B28,Sheet1!B28:D509,2,0) -> North | D28: CANDOR KOLKATA ONE HI-TECH STRUCTURES PVT. LTD | E28: CMES Cogen | F28: No | G28: Deepak.Dahiya@ap.jll.com;srijit.mukherjee@brookfieldproperties.com | H28: Parveen.KR@ap.jll.com;estate.managerG2@brookfield.com;sureshkumar.rana@brookfieldproperties.com;Manoj.Rajput@ap.jll.com | L28: =VLOOKUP(C28,Sheet1!A27:E501,2,0) -> #N/A
A29: 28 | B29: Unitech Sec-48-HR-Gurugram-199kWp Total | C29: =VLOOKUP(B29,Sheet1!B29:D510,2,0) -> North | D29: Candor Gurgaon One Developers & Projects Pvt Ltd | E29: CMES Cogen | F29: No | G29: estate.managerg1@brookfield.com;Krishan.Kumar@ap.jll.com | H29: Rupesh.Rai@ap.jll.com | L29: =VLOOKUP(C29,Sheet1!A28:E502,2,0) -> #N/A
A30: 29 | B30: BASF-MH-Mumbai-26.88kWp Total | C30: =VLOOKUP(B30,Sheet1!B30:D511,2,0) -> West | D30: BASF Chemicals India Pvt Ltd | E30: CMES IPP1 | F30: Yes | G30: #N/A | L30: =VLOOKUP(C30,Sheet1!A29:E503,2,0) -> #N/A
A31: 30 | B31: Minda (Plant-2)-HR-Rewari-100kWp Total | C31: =VLOOKUP(B31,Sheet1!B31:D512,2,0) -> North | D31: Furukawa Minda Electric Pvt. Ltd | E31: CMES IPP1 | F31: No | G31: Dileep.kumar@furukawaminda.com; | H31: marut.chaudhary@furukawaminda.com | L31: =VLOOKUP(C31,Sheet1!A30:E504,2,0) -> #N/A
A32: 31 | B32: Ministry of Earth Science-DL-New Delhi-60.8kWp Total | C32: =VLOOKUP(B32,Sheet1!B32:D513,2,0) -> North | D32: Ministry of Earth Science | E32: CMES IPP1 | F32: Yes | G32: ankit.jain@nic.in;praveen.kj@nic.in; vivek.sangwan@nic.in | L32: =VLOOKUP(C32,Sheet1!A31:E504,2,0) -> #N/A
A33: 32 | B33: Viviana Mall-MH-Thane-89.6kWp Total | C33: =VLOOKUP(B33,Sheet1!B33:D514,2,0) -> West | D33: Sheth Developers & Realtors (India) Limited | E33: CMES IPP1 | F33: No | G33: Devyani Bhosle <enghelpdesk@lakeshorein.com>, Subhash Ahuja <sahuja@lakeshorein.com>, Nitin Vichare <nvichare@lakeshorein.com>, Kapil Jadhav <kjadhav@lakeshorein.com>, Narayana Reddy Chintala <nchintala@lakeshorein.com>, Ranjeet Yadav <ryadav@lakeshorein.com>, Kumaravel R <kumaravel.r@cleanmax.com>, Logesh B <logesh.b@cleanmax.com>, Minal Vithlani <minal.vithlani@cleanmax.com>, Prasad Kulkarni <prasad.kulkarni@cleanmax.com>, Kaushal Kishore <kaushal.kishore@cleanmax.com>, Yash Lavhate <yash.lavhate@cleanmax.com> | H33: ganesh.shelar@vivianamalls.com; | L33: =VLOOKUP(C33,Sheet1!A32:E505,2,0) -> #N/A
A34: 33a | B34: NCMRWF-UP-Noida-158.1kWp Total 1 | C34: =VLOOKUP(B34,Sheet1!B34:D515,2,0) -> North | D34: National Center for Medium Range Weather Forecasting | E34: CMES IPP1 | F34: Yes | G34: Hema@ncmrwf.gov.in;anil@ncmrwf.gov.in | L34: =VLOOKUP(C34,Sheet1!A33:E506,2,0) -> #N/A
A35: 33b | B35: NCMRWF-UP-Noida-158.1kWp Total 2 | C35: =VLOOKUP(B35,Sheet1!B35:D516,2,0) -> North | D35: National Center for Medium Range Weather Forecasting | E35: CMES IPP1 | F35: Yes | G35: Hema@ncmrwf.gov.in;anil@ncmrwf.gov.in | L35: =VLOOKUP(C35,Sheet1!A34:E507,2,0) -> #N/A
A36: 34 | B36: NRCG-MH-Pune-70.4kWp Total | C36: =VLOOKUP(B36,Sheet1!B36:D517,2,0) -> West | D36: National Research Center for Grapes | E36: CMES IPP1 | F36: Yes | G36: Auditnrcgrapes Grapes <auditnrcgrapes@gmail.com>, kaliicarnrcg@gmail.com, "Director, ICAR-NRC Grapes, Pune" <dirnrcg@gmail.com>, Minal Vithlani <minal.vithlani@cleanmax.com>, Kumaravel R <kumaravel.r@cleanmax.com>, Logesh B <logesh.b@cleanmax.com>, "Westteam.am" <westteam.am@cleanmax.com> | H36: auditnrcgrapes@gmail.com | L36: =VLOOKUP(C36,Sheet1!A35:E508,2,0) -> #N/A
A37: 35 | B37: INCOIS-TS-Hyderabad-397kWp Total | C37: =VLOOKUP(B37,Sheet1!B37:D518,2,0) -> South | D37: Indian National Centre For Ocean Information Services | E37: CMES IPP1 | F37: Yes | G37: vijay@incois.gov.in;nbsubrahmanyam@incois.gov.in | L37: =VLOOKUP(C37,Sheet1!A36:E509,2,0) -> #N/A
A38: 36a | B38: DBSKKV-MH-Raatnagiri-241.92kWp Total 1 | C38: =VLOOKUP(B38,Sheet1!B38:D519,2,0) -> West | D38: Dr. Balasaheb Sawant Konkan Krishi Vidyapeeth | E38: CMES IPP1 | F38: Yes | G38: universityengineerdbskkv@gmail.com, regrdbskkv@rediffmail.com, regr.dbskkv@gov.in, Minal Vithlani <minal.vithlani@cleanmax.com>, Prasad Kulkarni <prasad.kulkarni@cleanmax.com>, Kumaravel R <kumaravel.r@cleanmax.com>, Yash Lavhate <yash.lavhate@cleanmax.com>, Logesh B <logesh.b@cleanmax.com> | L38: =VLOOKUP(C38,Sheet1!A37:E510,2,0) -> #N/A
A39: 36b | B39: DBSKKV-MH-Raatnagiri-241.92kWp Total 2 | C39: =VLOOKUP(B39,Sheet1!B39:D520,2,0) -> West | D39: Dr. Balasaheb Sawant Konkan Krishi Vidyapeeth | E39: CMES IPP1 | F39: Yes | G39: universityengineerdbskkv@gmail.com, regrdbskkv@rediffmail.com, regr.dbskkv@gov.in, Minal Vithlani <minal.vithlani@cleanmax.com>, Prasad Kulkarni <prasad.kulkarni@cleanmax.com>, Kumaravel R <kumaravel.r@cleanmax.com>, Yash Lavhate <yash.lavhate@cleanmax.com>, Logesh B <logesh.b@cleanmax.com> | L39: =VLOOKUP(C39,Sheet1!A38:E511,2,0) -> #N/A
A40: 36c | B40: DBSKKV-MH-Raatnagiri-241.92kWp Total 3 | C40: =VLOOKUP(B40,Sheet1!B40:D521,2,0) -> West | D40: Dr. Balasaheb Sawant Konkan Krishi Vidyapeeth | E40: CMES IPP1 | F40: Yes | G40: universityengineerdbskkv@gmail.com, regrdbskkv@rediffmail.com, regr.dbskkv@gov.in, Minal Vithlani <minal.vithlani@cleanmax.com>, Prasad Kulkarni <prasad.kulkarni@cleanmax.com>, Kumaravel R <kumaravel.r@cleanmax.com>, Yash Lavhate <yash.lavhate@cleanmax.com>, Logesh B <logesh.b@cleanmax.com> | L40: =VLOOKUP(C40,Sheet1!A39:E512,2,0) -> #N/A
...

Sheet Sheet1
A1: Customer Code in SAP | B1: Project Name | C1: Region | D1: O&M contact | E1: Invoice Created by | F1: TO | G1: CC | H1: Person Name
A2: 400057 | B2: Agharkar-MH-Pune-100.79kWp Total | C2: West | D2: Yash | E2: Gopi | F2: A V Chaudhari <avchaudhari@aripune.org>, Rahul G Birwadkar <rbirwadkar@aripune.org>, pv sawant <pvsawant@aripune.org>, Minal Vithlani <minal.vithlani@cleanmax.com>, "accounts ." <accounts@aripune.org>, Logesh B <logesh.b@cleanmax.com>, Prasad Kulkarni <prasad.kulkarni@cleanmax.com>, Kumaravel R <kumaravel.r@cleanmax.com> | G2: Minal Vithlani <minal.vithlani@cleanmax.com>; Kumaravel R <kumaravel.r@cleanmax.com> ; Logesh B <logesh.b@cleanmax.com>; westteam.am@cleanmax.com
A3: 400058 | B3: Manipal Resorts-KA-Bangalore-135kWp Total | C3: South | D3: Thirumaran | E3: Kanaga | F3: Venkatesh R <venkatesh.r@goodhostspaces.com>, anil.Kumar@goodhostspaces.com | G3: Thirumaran Ds <thirumaran.ds@cleanmax.com> | H3: Venkatesh
A4: 400059 | B4: Medha Servo-TS-Hyderabad-252kWp Total | C4: South | D4: Veeraju | E4: Kanaga | F4: nagenderkumark <nagenderkumark@medha.com> | G4: sudhakark@medha.com, sasikalat@medha.com, "Vani .Upputuru(HR)" <vaniu@medha.com>, Minal Vithlani <minal.vithlani@cleanmax.com>, P Veerraju <p.veerraju@cleanmax.com>, Logesh B <logesh.b@cleanmax.com>, Vignesh Venkatesan <vignesh.venkat@cleanmax.com>, Kumaravel R <kumaravel.r@cleanmax.com>, Thirumaran Ds <thirumaran.ds@cleanmax.com>
A5: 400060 | B5: Nestle-HR-Samalkha-300kWp Total | C5: North | D5: Ashutosh Kumar | E5: Raji | F5: NBS S2P <Generic.INInvoiceSAR01@in.nestle.com> | G5: Agarwal,Ayush,IN-Samalkha,S & IM Blue Collar - Operational Buying" <Ayush.Agarwal@in.nestle.com>
A6: 400273 | B6: Mahindra & Mahindra-MH-Nagpur-235kWp Total | C6: West | D6: Akshay Mohale | E6: Gopi | F6: JAIN RITESH-NGP <JAIN.RITESH1@mahindra.com>,JUNGHARE GUNWANTA <JUNGHARE.GUNWANTA@mahindra.com>, GOTMARE SURAJ <GOTMARE.SURAJ@mahindra.com>, Minal Vithlani <minal.vithlani@cleanmax.com>, Satish Chavan <satish.chavan@cleanmax.com>, Logesh B <logesh.b@cleanmax.com>, Kumaravel R <kumaravel.r@cleanmax.com>, Akshay Mohale <akshay.mohale@cleanmax.com> | G6: Minal Vithlani <minal.vithlani@cleanmax.com>; Kumaravel R <kumaravel.r@cleanmax.com> ; Logesh B <logesh.b@cleanmax.com>; westteam.am@cleanmax.com
A7: 400062 | B7: CPWD-MH-Pune-151kWp Total | C7: West | D7: Yash | E7: Gopi | F7: lbpune2@gmail.com | G7: Minal Vithlani <minal.vithlani@cleanmax.com>; Kumaravel R <kumaravel.r@cleanmax.com> ; Logesh B <logesh.b@cleanmax.com>; westteam.am@cleanmax.com
A8: 400287 | B8: MMM Sanand-GJ-Ahmedabad-192kWp Total | C8: West | D8: Yash | E8: Gopi | F8: "Rawat Vinod (MMLI)" <Vinod.rawat@marelli.motherson.com>, "Jagtap, Prasad (MMLI)" <Prasad.Jagtap@marelli.motherson.com>, Kumaravel R <kumaravel.r@cleanmax.com>, Yash Lavhate <yash.lavhate@cleanmax.com>; hiteshk.rohilla@marelli.motherson.com; Naveen.Agarwal01@marelli.motherson.com; maint.sanand@marelli.motherson.com | G8: Minal Vithlani <minal.vithlani@cleanmax.com>; Kumaravel R <kumaravel.r@cleanmax.com> ; Logesh B <logesh.b@cleanmax.com>; westteam.am@cleanmax.com
A9: 400167 | B9: CPWD-UP-Agra-50kWp Total | C9: North | D9: Abhishek Rai | E9: Raji | F9: Assistant Engineer Electrical <acesd.agra@gmail.com>, "S.P. Sharma EE(E)" <eebced@rediffmail.com
A10: 400065 | B10: CPWD-KA-Bangalore-75.6kWp Total | C10: South | D10: Thirumaran | E10: Kanaga | F10: bedcpwdbng@gmail.com, bcesd4cpwd.blr@gmail.com, vidhyaslm@gmail.com. | G10: sabin t <sabint.nls@gmail.com>, Paurush Chaturvedi <paurush.chaturvedi@cleanmaxsolar.com>, Minal Vithlani <minal.vithlani@cleanmax.com>, Logesh B <logesh.b@cleanmax.com>, Kumaravel R <kumaravel.r@cleanmax.com>, Dinesh Kumar <admin.chennai@cleanmax.com>, Thirumaran Ds <thirumaran.ds@cleanmax.com>, Manoj Kumar <manoj.kumar@cleanmax.com> | H10: Kishore kumar Umashankar
A11: 400217 | B11: IIT-BHU-UP-Varanasi-1518kWp Total | C11: North | D11: Abhishek Rai | E11: Raji | F11: office.iwd@iitbhu.ac.in, sbd.civ@iitbhu.ac.in, aecivil.iwd@itbhu.ac | G11: Assistant Engineer (Electrical) IWD, IIT (BHU)" <aeelectrical.iwd@itbhu.ac.in>, "Dr. S.K.Gupta" <skgupta.civ@iitbhu.ac.in
A12: 400067 | B12: Kendriya Sadan-TS-Hyderabad-100.8kWp Total | C12: South | D12: Veeraju | E12: Kanaga | F12: "aee hcesd2.cpwd" <aeehcesd2.cpwd@gmail.com> | G12: P Veerraju <p.veerraju@cleanmax.com>, Minal Vithlani <minal.vithlani@cleanmax.com>, Kumaravel R <kumaravel.r@cleanmax.com>, Logesh B <logesh.b@cleanmax.com>, Dinesh Kumar <admin.chennai@cleanmax.com>, Gokul N <gokul.n@cleanmax.com>
A13: 400251 | B13: Kendriya Sadan-MH-Belapur-37kWp Total | C13: West | D13: Yash | E13: Gopi | F13: MCED V <eeemcedv@gmail.com>, shachendra@yahoo.co.in, Kumaravel R <kumaravel.r@cleanmaxsolar.com>, Logesh B <logesh.b@cleanmax.com>, Minal Vithlani <minal.vithlani@cleanmax.com>, AEE3 MCED <aee3mced3cpwd@gmail.com>, Rakesh Kumar Sharma <sharmacpwd@gmail.com>, Assistant Engineer Mced <aee3mcedv@gmail.com>, "Westteam.am" <westteam.am@cleanmax.com> | G13: Minal Vithlani <minal.vithlani@cleanmax.com>; Kumaravel R <kumaravel.r@cleanmax.com> ; Logesh B <logesh.b@cleanmax.com>; westteam.am@cleanmax.com
A14: 400153 | B14: CGO-MH-Belapur-50.4kWp Total | C14: West | D14: Yash | E14: Gopi | F14: MCED V <eeemcedv@gmail.com>, shachendra@yahoo.co.in, Kumaravel R <kumaravel.r@cleanmaxsolar.com>, Logesh B <logesh.b@cleanmax.com>, Minal Vithlani <minal.vithlani@cleanmax.com>, AEE3 MCED <aee3mced3cpwd@gmail.com>, Rakesh Kumar Sharma <sharmacpwd@gmail.com>, Assistant Engineer Mced <aee3mcedv@gmail.com>, "Westteam.am" <westteam.am@cleanmax.com> | G14: Minal Vithlani <minal.vithlani@cleanmax.com>; Kumaravel R <kumaravel.r@cleanmax.com> ; Logesh B <logesh.b@cleanmax.com>; westteam.am@cleanmax.com
A15: 400157 | B15: CPWD-MH-Mumbai-50kWp Total | C15: West | D15: Yash | E15: Gopi | F15: sd2 mced1 <sd2_mced1@yahoo.co.in> | G15: Minal Vithlani <minal.vithlani@cleanmax.com>; Kumaravel R <kumaravel.r@cleanmax.com> ; Logesh B <logesh.b@cleanmax.com>; westteam.am@cleanmax.com
A16: 400071 | B16: CGO Complex-UP-Ghaziabad-126kWp Total | C16: North | D16: Ashutosh Kumar | E16: Raji | F16: aee1gcesd1hcedcpwd@gmail.com | G16: Kamlendra Kamal <kamal.kk.05@gmail.com>
A17: 400072 | B17: GPO-UP-Ghaziabad-113kWp Total | C17: North | D17: Ashutosh Kumar | E17: Raji | F17: aee1gcesd1hcedcpwd@gmail.com | G17: Kamlendra Kamal <kamal.kk.05@gmail.com>
A18: 400073 | B18: RAF-UP-Meerut-75kWp Total | C18: North | D18: Ashutosh Kumar | E18: Raji | F18: Computercell 108RAF <computercell108raf@gmail.com>, pramod KUMAR <sandeep108bn@gmail.com>
A19: 400074 | B19: NVTI-UP-Noida-115kWp Total | C19: North | D19: Ashutosh Kumar | E19: Raji | F19: nvti@nic.in
A20: 400075 | B20: MHEL-CHAKAN-MH-Pune-64kWp Total | C20: West | D20: Yash | E20: Gopi | F20: ENCHALWAR GAJANAN - MHEL <ENCHALWAR.GAJANAN@mahindra.com>, Prasad Kulkarni <prasad.kulkarni@cleanmax.com>, CHAVAN HEMANT-MHEL <CHAVAN.HEMANT@mahindra.com>, Minal Vithlani <minal.vithlani@cleanmax.com>, KUMAR ADITYA - MHEL <KUMAR.ADITYA203d22@mahindra.com>, Kumaravel R <kumaravel.r@cleanmax.com>, Logesh B <logesh.b@cleanmax.com> | G20: Minal Vithlani <minal.vithlani@cleanmax.com>; Kumaravel R <kumaravel.r@cleanmax.com> ; Logesh B <logesh.b@cleanmax.com>; westteam.am@cleanmax.com
A21: 400076 | B21: MHEL-CHAKAN-MH-Pune-211kWp Total | C21: West | D21: Yash | E21: Gopi | F21: ENCHALWAR GAJANAN - MHEL <ENCHALWAR.GAJANAN@mahindra.com>, Prasad Kulkarni <prasad.kulkarni@cleanmax.com>, CHAVAN HEMANT-MHEL <CHAVAN.HEMANT@mahindra.com>, Minal Vithlani <minal.vithlani@cleanmax.com>, KUMAR ADITYA - MHEL <KUMAR.ADITYA203d22@mahindra.com>, Kumaravel R <kumaravel.r@cleanmax.com>, Logesh B <logesh.b@cleanmax.com> | G21: Minal Vithlani <minal.vithlani@cleanmax.com>; Kumaravel R <kumaravel.r@cleanmax.com> ; Logesh B <logesh.b@cleanmax.com>; westteam.am@cleanmax.com
A22: 400077 | B22: KIOCL-KA-Mangalore-191.2kWp Total | C22: South | D22: Thirumaran | E22: Kanaga | F22: BFUELECTRICAL@KIOCLLTD.IN mfa@kioclltd.in | G22: Kumaravel R <kumaravel.r@cleanmaxsolar.com>, Minal Vithlani <minal.vithlani@cleanmax.com>, Logesh B <logesh.b@cleanmax.com>, Bhargav Venkatesh <bhargav.venkatesh@cleanmax.com>, Thirumaran Ds <thirumaran.ds@cleanmax.com> | H22: Ashwathanarayana KIOCL
A23: 400078 | B23: KIOCL-KA-Mangalore-102.4kWp Total | C23: South | D23: Thirumaran | E23: Kanaga | F23: BFUELECTRICAL@KIOCLLTD.IN mfa@kioclltd.in | G23: Kumaravel R <kumaravel.r@cleanmaxsolar.com>, Minal Vithlani <minal.vithlani@cleanmax.com>, Logesh B <logesh.b@cleanmax.com>, Bhargav Venkatesh <bhargav.venkatesh@cleanmax.com>, Thirumaran Ds <thirumaran.ds@cleanmax.com> | H23: Ashwathanarayana KIOCL
A24: 400079 | B24: KIOCL-KA-Mangalore-83.2kWp Total | C24: South | D24: Thirumaran | E24: Kanaga | F24: mppelec@kioclltd.in mfa@kioclltd.in | G24: Kumaravel R <kumaravel.r@cleanmaxsolar.com>, Minal Vithlani <minal.vithlani@cleanmax.com>, Logesh B <logesh.b@cleanmax.com>, Bhargav Venkatesh <bhargav.venkatesh@cleanmax.com>, Thirumaran Ds <thirumaran.ds@cleanmax.com>, Manoj Kumar <manoj.kumar@cleanmax.com> | H24: Anil Kumar
A25: 400277 | B25: Mahindra & Mahindra-RJ-Jaipur-269kWp Total | C25: West | D25: Govind | E25: Raji | F25: YADAV SATYAPRAKASH <YADAV.SATYAPRAKASH@mahindra.com>
A26: 400088 | B26: AMU-UP-Aligarh-1141.1kWp Total | C26: North | D26: Abhishek Rai | E26: Raji | F26: m.rihan.ee@amu.ac.in, Mohd Shamim Ansari <shamim_3747@rediffmail.com>
A27: 400096 | B27: AMU-UP-Aligarh-359.8kWp Total | C27: North | D27: Abhishek Rai | E27: Raji | F27: m.rihan.ee@amu.ac.in, Mohd Shamim Ansari <shamim_3747@rediffmail.com>
A28: 400083 | B28: Unitech Sec-21-HR-Gurugram-333.9kWp Total | C28: North | D28: Ashutosh Kumar | E28: Raji | F28: Dahiya, Deepak" <Deepak.Dahiya@jll.com | G28: KR, Parveen" <Parveen.KR@jll.com>, "Manager G2, Estate" <estate.managerg2@brookfield.com>, "Mukherjee, Srijit" <srijit.mukherjee@brookfieldproperties.com>, "Rana, Suresh" <sureshkumar.rana@brookfieldproperties.com>, "Rajput, Manoj" <Manoj.Rajput@jll.com>,"Ojha, Amit @ Gurgaon" <Amit.Ojha@cbre.com>
A29: 400359 | B29: Unitech Sec-48-HR-Gurugram-199kWp Total | C29: North | D29: Ashutosh Kumar | E29: Raji | F29: Yadav, RakeshY" <RakeshY.Yadav@jll.com> | G29: Bhat, Sharashchandra" <Sharashchandra.Bhat@jll.com>, "Rai, Rupesh" <Rupesh.Rai@jll.com>, "Kaushik, Sunil" <sunil.kaushik@brookfield.com>, "Manager G1, Estate" <estate.managerg1@brookfield.com>, "Singh, Roshan" <Roshan.Singh@jll.com>, "Jha, Anup" <Anup.Jha@jll.com>
A30: Shut down | B30: BASF-MH-Mumbai-26.88kWp Total | C30: West | D30: Yash | F30: Shut down | G30: Minal Vithlani <minal.vithlani@cleanmax.com>; Kumaravel R <kumaravel.r@cleanmax.com> ; Logesh B <logesh.b@cleanmax.com>; westteam.am@cleanmax.com
A31: 400286 | B31: Minda (Plant-2)-HR-Rewari-100kWp Total | C31: North | D31: Govind | E31: Raji | F31: Marut Chaudhary <marut.chaudhary@furukawaminda.com> | G31: Dileep kumar <dileep.kumar@furukawaminda.com>,
A32: 400087 | B32: Ministry of Earth Science-DL-New Delhi-60.8kWp Total | C32: North | D32: Ashutosh Kumar | E32: Raji | F32: ankit.jain@nic.in, Praveen Kumar Jain <praveen.kj@nic.in>
A33: 401318 | B33: Viviana Mall-MH-Thane-89.6kWp Total | C33: West | D33: Yash | E33: Gopi | F33: Devyani Bhosle <enghelpdesk@lakeshorein.com>, Subhash Ahuja <sahuja@lakeshorein.com>, Nitin Vichare <nvichare@lakeshorein.com>, Kapil Jadhav <kjadhav@lakeshorein.com>, Narayana Reddy Chintala <nchintala@lakeshorein.com>, Ranjeet Yadav <ryadav@lakeshorein.com>, Kumaravel R <kumaravel.r@cleanmax.com>, Logesh B <logesh.b@cleanmax.com>, Minal Vithlani <minal.vithlani@cleanmax.com>, Prasad Kulkarni <prasad.kulkarni@cleanmax.com>, Kaushal Kishore <kaushal.kishore@cleanmax.com>, Yash Lavhate <yash.lavhate@cleanmax.com> | G33: Minal Vithlani <minal.vithlani@cleanmax.com>; Kumaravel R <kumaravel.r@cleanmax.com> ; Logesh B <logesh.b@cleanmax.com>; westteam.am@cleanmax.com
A34: 400089 | B34: NCMRWF-UP-Noida-158.1kWp Total 1 | C34: North | D34: Ashutosh Kumar | E34: Raji | F34: Arun Kumar <arun@ncmrwf.gov.in
A35: 401225 | B35: NCMRWF-UP-Noida-158.1kWp Total 2 | C35: North | D35: Ashutosh Kumar | E35: Raji | F35: Arun Kumar <arun@ncmrwf.gov.in
A36: 400090 | B36: NRCG-MH-Pune-70.4kWp Total | C36: West | D36: Yash | E36: Gopi | F36: Auditnrcgrapes Grapes <auditnrcgrapes@gmail.com>, kaliicarnrcg@gmail.com, "Director, ICAR-NRC Grapes, Pune" <dirnrcg@gmail.com>, Minal Vithlani <minal.vithlani@cleanmax.com>, Kumaravel R <kumaravel.r@cleanmax.com>, Logesh B <logesh.b@cleanmax.com>, "Westteam.am" <westteam.am@cleanmax.com> | G36: Minal Vithlani <minal.vithlani@cleanmax.com>; Kumaravel R <kumaravel.r@cleanmax.com> ; Logesh B <logesh.b@cleanmax.com>; westteam.am@cleanmax.com
A37: 400091 | B37: INCOIS-TS-Hyderabad-397kWp Total | C37: South | D37: Veeraju | E37: Kanaga | F37: "Vijay G." <vijay@incois.gov.in>, NB Subrahmanyam <nbsubrahmanyam@incois.gov.in> | G37: Kumaravel R <kumaravel.r@cleanmax.com>, P Veerraju <p.veerraju@cleanmax.com>, Minal Vithlani <minal.vithlani@cleanmax.com>, Logesh B <logesh.b@cleanmax.com>
A38: 400092 | B38: DBSKKV-MH-Raatnagiri-241.92kWp Total 1 | C38: West | D38: Vinod Sonkamble | E38: Gopi | F38: universityengineerdbskkv@gmail.com, regrdbskkv@rediffmail.com, regr.dbskkv@gov.in, Minal Vithlani <minal.vithlani@cleanmax.com>, Prasad Kulkarni <prasad.kulkarni@cleanmax.com>, Kumaravel R <kumaravel.r@cleanmax.com>, Yash Lavhate <yash.lavhate@cleanmax.com>, Logesh B <logesh.b@cleanmax.com> | G38: Minal Vithlani <minal.vithlani@cleanmax.com>; Kumaravel R <kumaravel.r@cleanmax.com> ; Logesh B <logesh.b@cleanmax.com>; westteam.am@cleanmax.com
A39: 400093 | B39: DBSKKV-MH-Raatnagiri-241.92kWp Total 2 | C39: West | D39: Vinod Sonkamble | E39: Gopi | F39: universityengineerdbskkv@gmail.com, regrdbskkv@rediffmail.com, regr.dbskkv@gov.in, Minal Vithlani <minal.vithlani@cleanmax.com>, Prasad Kulkarni <prasad.kulkarni@cleanmax.com>, Kumaravel R <kumaravel.r@cleanmax.com>, Yash Lavhate <yash.lavhate@cleanmax.com>, Logesh B <logesh.b@cleanmax.com> | G39: Minal Vithlani <minal.vithlani@cleanmax.com>; Kumaravel R <kumaravel.r@cleanmax.com> ; Logesh B <logesh.b@cleanmax.com>; westteam.am@cleanmax.com
A40: 400094 | B40: DBSKKV-MH-Raatnagiri-241.92kWp Total 3 | C40: West | D40: Vinod Sonkamble | E40: Gopi | F40: universityengineerdbskkv@gmail.com, regrdbskkv@rediffmail.com, regr.dbskkv@gov.in, Minal Vithlani <minal.vithlani@cleanmax.com>, Prasad Kulkarni <prasad.kulkarni@cleanmax.com>, Kumaravel R <kumaravel.r@cleanmax.com>, Yash Lavhate <yash.lavhate@cleanmax.com>, Logesh B <logesh.b@cleanmax.com> | G40: Minal Vithlani <minal.vithlani@cleanmax.com>; Kumaravel R <kumaravel.r@cleanmax.com> ; Logesh B <logesh.b@cleanmax.com>; westteam.am@cleanmax.com
...
